Wed, 18 Oct 2017 15:20:31  UIM_Server  ERROR   	-  Endpoint instance has no attribute 'status'
           ['Traceback (most recent call last):\n', '  File "UnifiedService/webroot/bin/common/Dispatch.py", line 27, in GET\n', '  File "<string>", line 1, in <module>\n', "AttributeError: Endpoint instance has no attribute 'status'\n"]
Wed, 18 Oct 2017 15:58:26  UIM_Server  INFO   	-  Backend service initialized successfully.
Wed, 18 Oct 2017 15:58:27  UIM_Server  ERROR   	-  [Errno 98] Address already in use
           ['Traceback (most recent call last):\n', '  File "UnifiedService/webroot/bin/ServerStart.py", line 205, in <module>\n', '  File "UnifiedService/webroot/bin/ServerStart.py", line 148, in start\n', '  File "/opt/lenovo/UnifiedService/webroot/bin/web/application.py", line 313, in run\n    return wsgi.runwsgi(self.wsgifunc(*middleware))\n', '  File "UnifiedService/webroot/bin/ServerStart.py", line 114, in <lambda>\n', '  File "/opt/lenovo/UnifiedService/webroot/bin/web/wsgi.py", line 17, in runfcgi\n    return flups.WSGIServer(func, multiplexed=True, bindAddress=addr).run()\n', '  File "/usr/lib/python2.7/dist-packages/flup/server/fcgi.py", line 112, in run\n    sock = self._setupSocket()\n', '  File "/usr/lib/python2.7/dist-packages/flup/server/fcgi_base.py", line 1018, in _setupSocket\n    sock.bind(self._bindAddress)\n', '  File "/usr/lib/python2.7/socket.py", line 228, in meth\n    return getattr(self._sock,name)(*args)\n', 'error: [Errno 98] Address already in use\n']
Wed, 18 Oct 2017 15:58:53  UIM_Server  INFO   	-  Backend service initialized successfully.
Wed, 18 Oct 2017 16:11:18  UIM_Server  INFO   	-  Backend service initialized successfully.
